Workbook

Sheet Influencer Pricing Worksheet
K2: Notes
B4: Total Influencers | C4: =C5+C7+C9+C11 -> 0 | E4: Total Influencers | F4: =F7+F11+F9+F5 -> 0 | H4: Total Influencers | I4: =I5+I7+I9+I11 -> 0 | K4: Total # of Influencers on the campaign
B5: Home Gatherings | E5: Home Gatherings | H5: Home Gatherings | K5: Home Gatherings: typically includes an influencer hosting an event with other influencers or friends in the specific niche; gathering would be centered around featured products/brand and would include several posts during and post gathering/event
B6: Home Gatherings Rate | C6: 2000 | E6: Home Gatherings Rate | F6: 2000 | H6: Home Gatherings Rate | I6: 2000 | K6: Typically $2000 - $4000 depending on how many deliverables/posts are included
B7: Video Creators | E7: Video Creators | H7: Video Creators | K7: Video Creators: typically posts a TikTok or IG Reel and 2 stories
B8: Video Creators Rate | C8: 1000 | E8: Video Creators Rate | F8: 1000 | H8: Video Creators Rate | I8: 1000 | K8: Rates typically range between $800 - $2000
B9: Social + Stories | E9: Social + Stories | H9: Social + Stories | K9: Social + Stories: IG Carousel post and 3 stories
B10: Social + Stories Rate | C10: 600 | E10: Social + Stories Rate | F10: 600 | H10: Social + Stories Rate | I10: 600 | K10: Rates typically range between $500 - $1000
B11: Macro Influencer | E11: Macro Influencer | H11: Macro Influencer | K11: Macro Influencer: typically posts an IG Reel or TikTok, has over 500K followers
B12: Macro Influencer Rate | C12: 10000 | E12: Macro Influencer Rate | F12: 10000 | H12: Macro Influencer Rate | I12: 10000 | K12: $10,000 usually gives enough budget for higher end but can adjust based on how we classify the macro influencer in the proposal (lower rate for 250K followers, higher for 1MM, etc)
B13: Compensation Total | C13: =(C5*C6)+(C7*C8)+(C9*C10)+(C11*C12) -> 0 | E13: Compensation Total | F13: =(F5*F6)+(F7*F8)+(F9*F10)+(F11*F12) -> 0 | H13: Compensation Total | I13: =(I5*I6)+(I7*I8)+(I9*I10)+(I11*I12) -> 0 | K13: Total Influencer Compensation for campaign
B14: Click 2 Cart | C14: 4500 | E14: Click 2 Cart | F14: 4500 | H14: Click 2 Cart | I14: 4500 | K14: Click2Cart links start at $4,500 for one link and up to 6 items for a 6 week campaign. Any additional links, more than 6 items, or additional flight time will require x the standard rate for each instance (i.e., if you have 8 items for 1 link for a 6 week campaign, you would include $9,000 here)
B15: Paid Media Spend | E15: Paid Media Spend | F15: 0 | H15: Paid Media Spend | K15: Paid media spend, can fluctuate based on overall goals and total spend
B16: Paid Media + C2C | C16: =C14+C15 -> 4500 | E16: Paid Media + C2C | F16: =F14+F15 -> 4500 | H16: Paid Media + C2C | I16: =I14+I15 -> 4500 | K16: Total Paid media spend plus Click2Cart cost
B17: Product Cost | C17: 0 | E17: Product Cost | F17: 0 | H17: Product Cost | I17: 0 | K17: Product cost if needs to be included in overall budget; this is typically for higher end items (over $250) if it absolutely needs to be included to compensate influencers accordingly to purchase
B18: Shipping Cost | C18: 0 | E18: Shipping Cost | F18: 0 | H18: Shipping Cost | I18: 0 | K18: Shipping cost if Soapbox will be shipping products to influencers; typically isn't the case and influencers will usually go in-store to purchase product. I would only recommend this if product is not available yet and we're having to ship samples, or if we're shipping PR boxes
B19: Product & Shipping Total | C19: =C4*C17 -> 0 | E19: Product & Shipping Total | F19: =F4*F17 -> 0 | H19: Product & Shipping Total | I19: =I4*I17 -> 0 | K19: Tota Product & Shipping cost
B20: Analytics & Software | C20: 1000 | E20: Analytics & Software | F20: 1000 | H20: Analytics & Software | I20: 1000 | K20: Doesn't change; included to cover agency fees
B21: Community Costs | C21: 500 | E21: Community Costs | F21: 500 | H21: Community Costs | I21: 500 | K21: Doesn't change; included to cover agency fees
B22: Hiring Leeway/Performance Incentives | C22: 500 | E22: Hiring Leeway/Performance Incentives | F22: 500 | H22: Hiring Leeway/Performance Incentives | I22: 500 | K22: Hiring leeway included to negotiate with influencers on their compensation, usage rights, etc.
B23: Per Hour Internal Rate | C23: 250 | E23: Per Hour Internal Rate | F23: 250 | H23: Per Hour Internal Rate | I23: 250 | K23: Doesn't change unless approved by JT
B24: Time Management Hours | C24: 10 | E24: Time Management Hours | F24: 10 | H24: Time Management Hours | I24: 10
B25: Influencer Review | C25: 0 | E25: Influencer Review | F25: 0 | H25: Influencer Review | I25: 0
B26: Content Review (1 round) | C26: 0 | E26: Content Review (1 round) | F26: 0 | H26: Content Review (1 round) | I26: 0
B27: Time Management Cost | C27: =(C24+C25+C26)*C23 -> 2500 | E27: Time Management Cost | F27: =(F24+F25+F26)*F23 -> 2500 | H27: Time Management Cost | I27: =(I24+I25+I26)*I23 -> 2500 | K27: Total time management cost
B28: Time + Hard Costs | C28: =C13+C19+C20+C21+C22+C27+C16 -> 9000 | E28: Time + Hard Costs | F28: =F13+F19+F20+F21+F22+F27+F16 -> 9000 | H28: Time + Hard Costs | I28: =I13+I19+I20+I21+I22+I27+I16 -> 9000 | K28: Time management and hard costs (Compensation Total, Paid Media + C2C, Analytics & Software, Community Costs, Hiring Leeway, Time Management Cost Total)
B29: Total Cost with Markup | C29: =C28*1.8 -> 16200 | E29: Total Cost with Markup | F29: =F28*1.8 -> 16200 | H29: Total Cost with Markup | I29: =I28*1.8 -> 16200 | K29: Cost with 1.8x markup
B30: Withholding | C30: 0.06 | E30: Withholding | F30: 0.06 | H30: Withholding | I30: 0.06 | K30: Withholding %
B31: Program Total | C31: =((C29*C30)+C29) -> 17172 | E31: Program Total | F31: =(((F29*F30)+F29)) -> 17172 | H31: Program Total | I31: =((I29*I30)+I29) -> 17172 | K31: Total = (Total Cost with Markup x Witholding) + Total Cost with Markup

Sheet Insights Pricing Worksheet
B2: SocialListening | E2: shopperThink - half day | H2: Digital Surveys | K2: Store Visits | N2: Influencer Panel
B4: Software | C4: 1000 | E4: Hard Costs | F4: 3000 | H4: Participants | I4: 100 | K4: Participants | L4: 40 | N4: Participants | O4: 12
B5: Per Hour Internal Rate | C5: 175 | E5: Incentive Value | F5: 50 | H5: Participant Rate | I5: 0 | K5: Participant Rate | L5: 125 | N5: Participant Rate | O5: 200
B6: Time Management Hours | C6: =C7+C8+C9 -> 23 | E6: Incentive Quantity | F6: 12 | H6: Participant Total | I6: =SUM(I5)*I4 -> 0 | K6: Participant Total | L6: =SUM(L5)*L4 -> 5000 | N6: Participant Total | O6: =SUM(O5)*O4 -> 2400
B7: Insights | C7: 16 | E7: Incentive Total | F7: =F5*F6 -> 600 | H7: Incentive Value | I7: 150 | K7: Incentive Value | L7: 0 | N7: Incentive Value | O7: 0
B8: Build | C8: 2 | E8: Software | F8: 1000 | H8: Incentive Quantity | I8: 4 | K8: Incentive Quantity | L8: 0 | N8: Incentive Quantity | O8: 12
B9: Design | C9: 5 | E9: Women's Blogger | F9: 600 | H9: Incentive Total | I9: =I7*I8 -> 600 | K9: Incentive Total | L9: =L7*L4 -> 0 | N9: Incentive Total | O9: =O7*O4 -> 0
B10: Time Management Cost | C10: =C5*C6 -> 4025 | E10: Per Hour Internal Rate | F10: 175 | H10: Software | I10: 1000 | K10: Software | L10: 1000 | N10: Software | O10: 1000
B11: Total | C11: =C4+C10 -> 5025 | E11: Time Management Hours | F11: =SUM(F12:F14) -> 70 | H11: Women's Blogger | I11: 600 | K11: Women's Blogger | L11: 1200 | N11: Women's Blogger | O11: 600
B12: Program Total | C12: =C11*2 -> 10050 | E12: Soapbox | F12: 40 | H12: Per Hour Internal Rate | I12: 175 | K12: Per Hour Internal Rate | L12: 175 | N12: Per Hour Internal Rate | O12: 175
E13: Admin | F13: 15 | H13: Time Management Hours | I13: =SUM(I14:I16) -> 40 | K13: Time Management Hours | L13: =SUM(L14:L16) -> 40 | N13: Time Management Hours | O13: =SUM(O14:O16) -> 34
E14: Design | F14: 15 | H14: Soapbox | I14: 20 | K14: Soapbox | L14: 20 | N14: Soapbox | O14: 16
E15: Time Management Cost | F15: =F10*F11 -> 12250 | H15: Admin | I15: 10 | K15: Admin | L15: 10 | N15: Admin | O15: 10
E16: Total | F16: =F4+F7+F8+F9+F15 -> 17450 | H16: Design | I16: 10 | K16: Design | L16: 10 | N16: Design | O16: 8
E17: Program Total | F17: =F16*2 -> 34900 | H17: Time Management Cost | I17: =I12*I13 -> 7000 | K17: Time Management Cost | L17: =L12*L13 -> 7000 | N17: Time Management Cost | O17: =O12*O13 -> 5950
H18: Total | I18: =I6+I9+I10+I11+I17 -> 9200 | K18: Total | L18: =L6+L9+L10+L11+L17 -> 14200 | N18: Total | O18: =O6+O9+O10+O11+O17 -> 9950
H19: Program Total | I19: =I18*2 -> 18400 | K19: Program Total | L19: =L18*2 -> 28400 | N19: Program Total | O19: =O18*2 -> 19900

Sheet Insights Pricing Worksheet (1)
B2: SocialListening | E2: shopperThink - half day | H2: Digital Surveys | K2: Store Visits | N2: Influencer Panel
B4: Software | C4: 1000 | E4: Hard Costs | F4: 3000 | H4: Participants | I4: 100 | K4: Participants | L4: 40 | N4: Participants | O4: 12
B5: Per Hour Internal Rate | C5: 175 | E5: Incentive Value | F5: 50 | H5: Participant Rate | I5: 0 | K5: Participant Rate | L5: 125 | N5: Participant Rate | O5: 200
B6: Time Management Hours | C6: =C7+C8+C9 -> 23 | E6: Incentive Quantity | F6: 12 | H6: Participant Total | I6: =SUM(I5)*I4 -> 0 | K6: Participant Total | L6: =SUM(L5)*L4 -> 5000 | N6: Participant Total | O6: =SUM(O5)*O4 -> 2400
B7: Insights | C7: 16 | E7: Incentive Total | F7: =F5*F6 -> 600 | H7: Incentive Value | I7: 150 | K7: Incentive Value | L7: 0 | N7: Incentive Value | O7: 0
B8: Build | C8: 2 | E8: Software | F8: 1000 | H8: Incentive Quantity | I8: 4 | K8: Incentive Quantity | L8: 0 | N8: Incentive Quantity | O8: 12
B9: Design | C9: 5 | E9: Women's Blogger | F9: 600 | H9: Incentive Total | I9: =I7*I8 -> 600 | K9: Incentive Total | L9: =L7*L4 -> 0 | N9: Incentive Total | O9: =O7*O4 -> 0
B10: Time Management Cost | C10: =C5*C6 -> 4025 | E10: Per Hour Internal Rate | F10: 175 | H10: Software | I10: 1000 | K10: Software | L10: 1000 | N10: Software | O10: 1000
B11: Total | C11: =C4+C10 -> 5025 | E11: Time Management Hours | F11: =SUM(F12:F14) -> 70 | H11: Women's Blogger | I11: 600 | K11: Women's Blogger | L11: 1200 | N11: Women's Blogger | O11: 600
B12: Program Total | C12: =C11*2 -> 10050 | E12: Soapbox | F12: 40 | H12: Per Hour Internal Rate | I12: 175 | K12: Per Hour Internal Rate | L12: 175 | N12: Per Hour Internal Rate | O12: 175
E13: Admin | F13: 15 | H13: Time Management Hours | I13: =SUM(I14:I16) -> 40 | K13: Time Management Hours | L13: =SUM(L14:L16) -> 40 | N13: Time Management Hours | O13: =SUM(O14:O16) -> 34
E14: Design | F14: 15 | H14: Soapbox | I14: 20 | K14: Soapbox | L14: 20 | N14: Soapbox | O14: 16
E15: Time Management Cost | F15: =F10*F11 -> 12250 | H15: Admin | I15: 10 | K15: Admin | L15: 10 | N15: Admin | O15: 10
E16: Total | F16: =F4+F7+F8+F9+F15 -> 17450 | H16: Design | I16: 10 | K16: Design | L16: 10 | N16: Design | O16: 8
E17: Program Total | F17: =F16*2 -> 34900 | H17: Time Management Cost | I17: =I12*I13 -> 7000 | K17: Time Management Cost | L17: =L12*L13 -> 7000 | N17: Time Management Cost | O17: =O12*O13 -> 5950
H18: Total | I18: =I6+I9+I10+I11+I17 -> 9200 | K18: Total | L18: =L6+L9+L10+L11+L17 -> 14200 | N18: Total | O18: =O6+O9+O10+O11+O17 -> 9950
H19: Program Total | I19: =I18*2 -> 18400 | K19: Program Total | L19: =L18*2 -> 28400 | N19: Program Total | O19: =O18*2 -> 19900

Sheet Calculator
B3: Organic Impressions | H3: *Paid Impressions
B4: Min | C4: Max | D4: Average | E4: Median | H4: Min Per $1k | I4: Max Per $1k | J4: Average Per $1k | K4: Median Per $1k | M4: Impressions
B5: #ERROR! | C5: =MAX('Data '!F:F) -> 2320675 | D5: =AVERAGE('Data '!F:F) -> 173300.2 | E5: =MEDIAN('Data '!F:F) -> 113770.8 | H5: =MIN('Data '!J:J)*1000 -> 0 | I5: =MAX('Data '!J:J)*1000 -> 3460092 | J5: =AVERAGE('Data '!J:J)*1000 -> 1039224.6 | K5: =MEDIAN('Data '!J:J)*1000 -> 991388.77 | M5: Can vary based on seasonality of program
M6: This tracker takes into account all programs, holiday or not, but you
B7: Total Influencers | D7: Estimated Impression | H7: Total Spend | J7: Estimated Impression | M7: will need to use with care when you estimate programs with paid media
B8: Enter Here | C8: 4 | D8: =C8*E5 -> 455083.2 | H8: Enter Here | I8: 1000 | J8: =I8*(AVERAGE('Data '!J2:J314)) -> 1053436.9 | M8: running over the holidays
M9: **If client is wanting lots of eyes on a post, use this!**
B11: Engagements | H11: *Paid Clicks
B12: Min | C12: Max | D12: Average | E12: Median | H12: Min Per $1k | I12: Max Per $1k | J12: Average Per $1k | K12: Median Per $1k | M12: Clicks
B13: =MIN('Data '!G:G) -> 157 | C13: =MAX('Data '!G:G) -> 2176231.5 | D13: =AVERAGE('Data '!G:G) -> 62705.616 | E13: =MEDIAN('Data '!G:G) -> 9148.5556 | H13: =MIN('Data '!P:P)*1000 -> 0 | I13: =MAX('Data '!P:P)*1000 -> 34367.703 | J13: =AVERAGE('Data '!P:P)*1000 -> 8399.2972 | K13: =MEDIAN('Data '!P:P)*1000 -> 7678.6045 | M13: If you use Click2Cart in a program, YOU NEED TO FACTOR IN CLICK PAID MEDIA
M14: **If client wants lots of potential sales and adds to cart, use this**
B15: Total Influencers | D15: Estimated Engagements | H15: Total Spend | J15: Estimated Clicks
B16: Enter Here | C16: 4 | D16: =C16*E13 -> 36594.222 | H16: Enter Here | J16: =I16*(AVERAGE('Data '!P:P)) -> 0
H19: *Paid Engagements
B20: Impressions + Engagements Estimates | D20: Good | E20: Better | F20: Best
B21: Organic + Paid Impressions: | D21: =D8+J8 -> 1508520.1 | E21: =D8+J8 -> 1508520.1 | F21: =D8+J8 -> 1508520.1 | H21: Min Per $1k | I21: Max Per $1k | J21: Average Per $1k | K21: Median Per $1k | M21: Engagements
B22: Organic + Paid Engagements/Clicks: | D22: =D16+J16+J25 -> 266659.12 | E22: =D16+J16+J25 -> 266659.12 | F22: =D16+J16+J25 -> 266659.12 | H22: =MIN('Data '!M:M)*1000 -> 0 | I22: =MAX('Data '!M:M)*1000 -> 1929982.9 | J22: =AVERAGE('Data '!M:M)*1000 -> 230064.9 | K22: =MEDIAN('Data '!M:M)*1000 -> 196960.5 | M22: We typically don't run a lot of programs off of Engagements (not unwilling, just doesn't usually align with the program strategy)
B23: Copy > Paste Special > Values & Number Formatting, before moving on to your next option
H24: Total Spend | J24: Estimated Paid Engagements**
B25: Media Breakout (for internal use only) | D25: Good | E25: Better | F25: Best | H25: Enter Here | I25: 1000 | J25: =I25*(AVERAGE('Data '!M:M)) -> 230064.9
B26: Paid Impressions: | D26: =I8 -> 1000 | E26: =I8 -> 1000 | F26: =I8 -> 1000 | M26: **This is only if the program strategy and client is looking for high engagement (likes, comments, shares on posts)**
B27: Paid Clicks: | D27: =I16 -> 0 | E27: =I16 -> 0 | F27: =I16 -> 0
B28: Paid Engagements: | D28: =I25 -> 1000 | E28: =I25 -> 1000 | F28: =I25 -> 1000 | M28: **includes Video Engagements which are substantially easier to get than static image engagements
B29: Total Paid Media Spend: | D29: =SUM(D26:D28) -> 2000 | E29: =SUM(E26:E28) -> 2000 | F29: =SUM(F26:F28) -> 2000

Sheet Data 
A1: Program | B1: Date | C1: # of Influencers | D1: Engagements | E1: Organic Impressions | F1: Impressions Per Influencer | G1: Engagements Per Influencer | H1: Paid Impressions | I1: Paid Spend (Impressions) | J1: Impressions per $1 Spend | K1: Paid Engagement | L1: Paid Spend (Engagement) | M1: Engagements per $1 | N1: Paid Clicks | O1: Paid Spend (Clicks) | P1: Clicks per $1
A2: #EggceptionallGreat | B2: 43999 | C2: 49 | D2: 36300 | E2: 2700000 | F2: =E2/C2 -> 55102.041 | G2: =D2/C2 -> 740.81633 | H2: 5413016 | I2: 4883 | J2: =H2/I2 -> 1108.5431
A3: #CelebrateWithWalmart | B3: 44008 | C3: 48 | D3: 37900 | E3: 1600000 | F3: =E3/C3 -> 33333.333 | G3: =D3/C3 -> 789.58333 | H3: 5413016 | I3: 4883 | J3: =H3/I3 -> 1108.5431
A4: #CelebrateWithHEB | B4: 43956 | C4: 33 | D4: 17400 | E4: 1130000 | F4: =E4/C4 -> 34242.424 | G4: =D4/C4 -> 527.27273 | H4: 1670000 | I4: 3000 | J4: =H4/I4 -> 556.66667
A5: #AllGoodAtWalmart | B5: 43964 | C5: 41 | D5: 113100 | E5: 602989 | F5: =E5/C5 -> 14707.049 | G5: =D5/C5 -> 2758.5366 | H5: 5697011 | I5: 4888.73 | J5: =H5/I5 -> 1165.3356
A6: #EggceptionallyGreat | B6: 43971 | C6: 49 | D6: 36300 | E6: 2700000 | F6: =E6/C6 -> 55102.041 | G6: =D6/C6 -> 740.81633
A7: #PAWatWalmart | B7: 44076 | C7: 8 | D7: 10500 | E7: 292000 | F7: =E7/C7 -> 36500 | G7: =D7/C7 -> 1312.5
A8: #AdventureForceFireandRescue and #AdventureForceSharkGarage | B8: 44095 | C8: 32 | D8: 34200 | E8: 2080000 | F8: =E8/C8 -> 65000 | G8: =D8/C8 -> 1068.75
A9: #LifemadeCoolerFall20 | B9: 44095 | C9: 14 | D9: 11400 | E9: 501253 | F9: =E9/C9 -> 35803.786 | G9: =D9/C9 -> 814.28571 | H9: 1100000 | I9: 1000 | J9: =H9/I9 -> 1100
A10: #SipLifemadeFall20 | B10: 44097 | C10: 24 | D10: 26200 | E10: 2360000 | F10: =E10/C10 -> 98333.333 | G10: =D10/C10 -> 1091.6667 | H10: 2600000 | I10: 3200 | J10: =H10/I10 -> 812.5
A11: #InnovasianOccasionWithPublix and #InnovasionOccasionWithWalmart | B11: 44102 | C11: 65 | D11: 50500 | E11: 7000000 | F11: =E11/C11 -> 107692.31 | G11: =D11/C11 -> 776.92308 | H11: 8400000 | I11: 10000 | J11: =H11/I11 -> 840
A12: #RegisterAsADoer | B12: 44102 | C12: 24 | D12: 18600 | E12: 713823 | F12: =E12/C12 -> 29742.625 | G12: =D12/C12 -> 775 | H12: 1136177 | I12: 1200 | J12: =H12/I12 -> 946.81417
A13: #DecorateWithWalmart | B13: 44119 | C13: 74 | D13: 92927 | E13: 4970793 | F13: =E13/C13 -> 67172.878 | G13: =D13/C13 -> 1255.7703 | H13: 9829207 | I13: 10000 | J13: =H13/I13 -> 982.9207
A14: #GroceryGifting2020 | B14: 44122 | C14: 40 | D14: 29710 | E14: 3600000 | F14: =E14/C14 -> 90000 | G14: =D14/C14 -> 742.75 | H14: 1300000 | I14: 2000 | J14: =H14/I14 -> 650
A15: #SaveMoneyGivePlush | B15: 44137 | C15: 6 | D15: 8100 | E15: 110000 | F15: =E15/C15 -> 18333.333 | G15: =D15/C15 -> 1350 | H15: 3020000 | I15: 3200 | J15: =H15/I15 -> 943.75
A16: #RemingtonReadyWithWalmart | B16: 44144 | C16: 41 | D16: 30411 | E16: 4029182 | F16: =E16/C16 -> 98272.732 | G16: =D16/C16 -> 741.73171 | H16: 2669406 | I16: 5000 | J16: =H16/I16 -> 533.8812
A17: #BlueHolidaysAtWalmart | B17: 44151 | C17: 41 | D17: 104100 | E17: 6629113 | F17: =E17/C17 -> 161685.68 | G17: =D17/C17 -> 2539.0244 | H17: 4324277 | I17: 4000 | J17: =H17/I17 -> 1081.0693
A18: #GiftingGreatWithWalgreens | B18: 44151 | C18: 75 | D18: 77600 | E18: 5000000 | F18: =E18/C18 -> 66666.667 | G18: =D18/C18 -> 1034.6667 | H18: 4600000 | I18: 5000 | J18: =H18/I18 -> 920
A19: #SaveMoneyGiveBetter2020 | B19: 44151 | C19: 56 | D19: 44836 | E19: 5690123 | F19: =E19/C19 -> 101609.34 | G19: =D19/C19 -> 800.64286 | H19: 3500000 | I19: 5000 | J19: =H19/I19 -> 700
A20: #MikesHotHoneyHoliday | B20: 44166 | C20: 26 | D20: 22900 | E20: 2911115 | F20: =E20/C20 -> 111965.96 | G20: =D20/C20 -> 880.76923 | H20: 2088885 | I20: 1500 | J20: =H20/I20 -> 1392.59 | K20: 52882 | L20: 2500 | M20: =K20/L20 -> 21.1528
A21: #JustOneGameNightAtWalmart | B21: 44183 | C21: 47 | D21: 38277 | E21: 5062810 | F21: =E21/C21 -> 107719.36 | G21: =D21/C21 -> 814.40426 | H21: 3603947 | I21: 3000 | J21: =H21/I21 -> 1201.3157
A22: #HEBeautifulWithEssano | B22: 04/31/21 | C22: 3 | D22: 6740 | E22: 1139356 | F22: =E22/C22 -> 379785.33 | G22: =D22/C22 -> 2246.6667
A23: #ZotekiCollectiblesAtAmazon | B23: 44307 | C23: 6 | D23: 13000 | E23: 680042 | F23: =E23/C23 -> 113340.33 | G23: =D23/C23 -> 2166.6667 | H23: 15510344 | I23: 10025 | J23: =H23/I23 -> 1547.1665 | N23: 59540 | O23: 10025 | P23: =N23/O23 -> 5.9391521
A24: #DurexAtWalmart | B24: 44295 | C24: 36 | D24: 39890 | E24: 1094570 | F24: =E24/C24 -> 30404.722 | G24: =D24/C24 -> 1108.0556 | H24: 4939413 | I24: 14200.14 | J24: =H24/I24 -> 347.84256 | N24: 50308 | O24: 10200.14 | P24: =N24/O24 -> 4.9320892
A25: #OrgainProteinAtWalmart | B25: 04/31/21 | C25: 34 | D25: 22548 | E25: 2305424 | F25: =E25/C25 -> 67806.588 | G25: =D25/C25 -> 663.17647 | H25: 2228161 | I25: 4500 | J25: =H25/I25 -> 495.14689 | N25: 9500 | O25: 2000 | P25: =N25/O25 -> 4.75
A26: #HydrantAtCVS | B26: 44338 | C26: 14 | D26: 7049 | E26: 2130117 | F26: =E26/C26 -> 152151.21 | G26: =D26/C26 -> 503.5 | H26: 1515385 | I26: 3000 | J26: =H26/I26 -> 505.12833 | K26: 9044 | L26: 1000 | M26: =K26/L26 -> 9.044
A27: #RemingtonVolumizingBrushAtWalmart | B27: 44338 | C27: 32 | D27: 55728 | E27: 2009658 | F27: =E27/C27 -> 62801.812 | G27: =D27/C27 -> 1741.5 | N27: 16593 | O27: 5000 | P27: =N27/O27 -> 3.3186
A28: #EssanoInTheUSA | B28: 44356 | C28: 15 | D28: 13233 | E28: 1957925 | F28: =E28/C28 -> 130528.33 | G28: =D28/C28 -> 882.2
A29: #RemingtonAir3DAtWalmart | B29: 44338 | C29: 36 | D29: 38874 | E29: 2538042 | F29: =E29/C29 -> 70501.167 | G29: =D29/C29 -> 1079.8333 | N29: 15794 | O29: 5000 | P29: =N29/O29 -> 3.1588
A30: #GiftGreatWithWalgreens | B30: 44367 | C30: 40 | D30: 24088 | E30: 2178310 | F30: =E30/C30 -> 54457.75 | G30: =D30/C30 -> 602.2 | H30: 5257759 | I30: 9100 | J30: =H30/I30 -> 577.77571
A31: #CatopiaAtWalmart | B31: 44377 | C31: 34 | D31: 105193 | E31: 5225596 | F31: =E31/C31 -> 153694 | G31: =D31/C31 -> 3093.9118 | H31: 2701753 | I31: 4000 | J31: =H31/I31 -> 675.43825
A32: Nick Great Outdoors | B32: 44382 | C32: 8 | D32: 5998 | E32: 389925 | F32: =E32/C32 -> 48740.625 | G32: =D32/C32 -> 749.75 | H32: 2414610 | I32: 2231 | J32: =H32/I32 -> 1082.2994
A33: SpongeBob Americana | B33: 44372 | C33: 5 | D33: 6482 | E33: 192769 | F33: =E33/C33 -> 38553.8 | G33: =D33/C33 -> 1296.4 | H33: 2032265 | I33: 1738 | J33: =H33/I33 -> 1169.3124
A34: #BlueTreatsAtWalmart | B34: 44377 | C34: 44 | D34: 78921 | E34: 5029996 | F34: =E34/C34 -> 114318.09 | G34: =D34/C34 -> 1793.6591 | H34: 1738553 | I34: 2500 | J34: =H34/I34 -> 695.4212
A35: #EggceptionallyGreat | B35: 44382 | C35: 10 | D35: 21982 | E35: 4183479 | F35: =E35/C35 -> 418347.9 | G35: =D35/C35 -> 2198.2 | H35: 3229200 | I35: 5000 | J35: =H35/I35 -> 645.84 | N35: 12769 | O35: 3390.23 | P35: =N35/O35 -> 3.7664111
A36: #YouCantHavePizzaWithoutMikes | B36: 44378 | C36: 24 | D36: 30627 | E36: 1269550 | F36: =E36/C36 -> 52897.917 | G36: =D36/C36 -> 1276.125 | H36: 4388623 | I36: 2819 | J36: =H36/I36 -> 1556.8013 | N36: 19896 | O36: 3000 | P36: =N36/O36 -> 6.632
A37: #LunchWithLM | B37: 44378 | C37: 18 | D37: 23740 | E37: 1135994 | F37: =E37/C37 -> 63110.778 | G37: =D37/C37 -> 1318.8889 | H37: 3931788 | I37: 3700 | J37: =H37/I37 -> 1062.6454 | K37: 20699 | L37: 1300 | M37: =K37/L37 -> 15.922308
A38: #LalaSummerAtWalmart | B38: 44408 | C38: 26 | D38: 36623 | E38: 2110110 | F38: =E38/C38 -> 81158.077 | G38: =D38/C38 -> 1408.5769 | H38: 4558068 | I38: 5000 | J38: =H38/I38 -> 911.6136 | N38: 20912 | O38: 8000 | P38: =N38/O38 -> 2.614
A39: #SummertimeGametime | B39: 44383 | C39: 26 | D39: 908338 | E39: 2445720 | F39: =E39/C39 -> 94066.154 | G39: =D39/C39 -> 34936.077 | H39: 2158468 | I39: 2941.53 | J39: =H39/I39 -> 733.79092
A40: #BobsAtSprouts | B40: 44396 | C40: 40 | D40: 24138 | E40: 2883530 | F40: =E40/C40 -> 72088.25 | G40: =D40/C40 -> 603.45 | H40: 1024627 | I40: 1500 | J40: =H40/I40 -> 683.08467
...

Sheet Margin
B3: GOOD | E3: BETTER | H3: BEEST
B4: Total Hard Costs | C4: =SUM('Influencer Pricing Worksheet'!C13,'Influencer Pricing Worksheet'!C16,'Influencer Pricing Worksheet'!C27,'Influencer Pricing Worksheet'!C19,'Influencer Pricing Worksheet'!C22) -> 7500 | E4: Total Hard Costs | F4: =SUM('Influencer Pricing Worksheet'!F13,'Influencer Pricing Worksheet'!F16,'Influencer Pricing Worksheet'!F27,'Influencer Pricing Worksheet'!F19,'Influencer Pricing Worksheet'!F22) -> 7500 | H4: Total Hard Costs | I4: =SUM('Influencer Pricing Worksheet'!I13,'Influencer Pricing Worksheet'!I16,'Influencer Pricing Worksheet'!I27,'Influencer Pricing Worksheet'!I19,'Influencer Pricing Worksheet'!I22) -> 7500
B5: Profit $ | C5: ='Influencer Pricing Worksheet'!C31-Margin!C4 -> 9672 | E5: Profit $ | F5: ='Influencer Pricing Worksheet'!F31-Margin!F4 -> 9672 | H5: Profit $ | I5: ='Influencer Pricing Worksheet'!I31-Margin!I4 -> 9672
B6: Profit Margin | C6: =C5/'Influencer Pricing Worksheet'!C31 -> 0.56324249 | E6: Profit Margin | F6: =F5/'Influencer Pricing Worksheet'!F31 -> 0.56324249 | H6: Profit Margin | I6: =I5/'Influencer Pricing Worksheet'!I31 -> 0.56324249
